<mujoco model="ur3">
    
    <option gravity = "0 0 0" timestep="0.01">
        <!--flag gravity="disable"/-->

    </option>
    
    <compiler angle="radian" meshdir="meshes" />
    <size njmax="500" nconmax="100" />

    <default>
        <light castshadow="false" diffuse="1 1 1" />
        <joint limited="true"
               damping="1"/><!--frictionloss = 1, defualt was 0--> 
        <!--geom solref="0.02 1"
              solimp="1 1 0"/-->
 
        <camera fovy="60" />
        <motor gear="0.8"/>
        <velocity kv="10"/>
        <position kp="5"/>
    </default>

    <asset>
   

        <mesh file="ur3_base.stl" name="base"></mesh>
        <mesh file="ur3_shoulder.stl" name="shoulder"></mesh>
        <mesh file="ur3_upperarm.stl" name="upperarm"></mesh>
        <mesh file="ur3_forearm.stl" name="forearm"></mesh>
        <mesh file="ur3_wrist1.stl" name="wrist1"></mesh>
        <mesh file="ur3_wrist2.stl" name="wrist2"></mesh>
        <mesh file="ur3_wrist3.stl" name="wrist3"></mesh>


        <mesh file="kinova_robotiq_coupler.stl" />
        <mesh file="robotiq_85_base_link.stl" />
        <mesh file="robotiq_85_finger_link.stl" />
        <mesh file="robotiq_85_finger_tip_link.stl" />
        <mesh file="robotiq_85_inner_knuckle_link.stl" />
        <mesh file="robotiq_85_knuckle_link.stl" />

        <material name="robot0:geomMat" shininess="0.03" specular="0.4"></material>
        <material name="robot0:gripper_finger_mat" shininess="0.03" specular="0.4" reflectance="0"></material>
        <material name="robot0:gripper_mat" shininess="0.03" specular="0.4" reflectance="0"></material>
        <material name="robot0:arm_mat" shininess="0.03" specular="0.4" reflectance="0"></material>
        <material name="robot0:head_mat" shininess="0.03" specular="0.4" reflectance="0"></material>
        <material name="robot0:torso_mat" shininess="0.03" specular="0.4" reflectance="0"></material>
        <material name="robot0:base_mat" shininess="0.03" specular="0.4" reflectance="0"></material>

        <material name="RobMat" specular="0.9" shininess="0.5" reflectance="0" rgba="0.7 0.7 0.7 1" emission="0.1" />
        <material name="GriMat" specular="0.9" shininess="0.5" reflectance="0" rgba="0.1 0.1 0.1 1" emission="0.1" />
        <material name="BasketMat" specular="0" shininess="0" reflectance="0" rgba="0.26 0.16 0.16796875 1" emission="0" />
        <material name="Light" specular="0" shininess="0.6" reflectance="0.9" rgba="0.5 0.5 1 1" emission="0.7" />
        

    </asset>
    <worldbody>
        <body pos="-0.16 0.20 0.02" euler="4.71238898 0 3.14159265">
            <body euler="0 -0.82 0">
                <camera name="workbench_camera" euler="0.25 0 0" fovy="43" />
            </body>
        </body>
        <body pos="-0.85 0.7 0.64" euler="4.71238898 0 3.14159265">
            <body euler="-0.3 0 0">
                <camera name="upper_camera" euler="0 0.09 0" fovy="41" />
            </body>
        </body>

        <light directional="true" pos="-0.5 0.5 3" dir="0 0 -1" />
        <light directional="false" pos="-0.5 0.5 1.5" dir="0 -1 0" />
        <geom name="workbench_down" pos="-0.6 0.6 -0.25" size="0.6 0.6 0.25" type="box" rgba="0 0 0 1"  />
        <geom name="floor" pos="0 0 -0.66" size="10 10 1" type="plane" rgba="1 0.83 0.61 1" />
        <geom name="wall_1" pos="0 -1.4 1" size="2.5 2.5 1" type="plane" quat="0.707107 -0.707107 0 0" rgba="0.95 0.95 0.95 1"  />
        <geom name="wall_2" pos="-2.185 0 1" size="2.5 2.5 1" type="plane" quat="0.707107 0 0.707107 0" rgba="0.95 0.95 0.95 1"  />


        <body name="base_link" pos="0 0 0">
            <inertial pos="0 0 0" quat="0.5 0.5 -0.5 0.5" mass="2" diaginertia="0.005625 0.00305317 0.00305317" />
            <geom type="mesh" rgba="0.7 0.7 0.7 1" mesh="base" material="robot0:base_mat" />
            <body name="shoulder_link" pos="0 0 0.1519">
                <inertial pos="0 0 0" mass="2" diaginertia="0.00809316 0.00809316 0.005625" />
                <joint name="shoulder_pan_joint" pos="0 0 0" axis="0 0 1" limited="true" range="-6.28319 6.28319" />
                <geom type="mesh" rgba="0.7 0.7 0.7 1" mesh="shoulder" material="robot0:head_mat" />
                <body name="upper_arm_link" pos="0 0.1198 0" quat="0.707107 0 0.707107 0">
                    <inertial pos="0 0 0.121825" mass="3.42" diaginertia="0.0217285 0.0217285 0.00961875" />
                    <joint name="shoulder_lift_joint" pos="0 0 0" axis="0 1 0" limited="true" range="-6.28319 6.28319" />
                    <geom type="mesh" rgba="0.7 0.7 0.7 1" mesh="upperarm" material="robot0:head_mat" />
                    <body name="forearm_link" pos="0 -0.0925 0.24365">
                        <inertial pos="0 0 0.106625" mass="1.26" diaginertia="0.00654681 0.00654681 0.00354375" />
                        <joint name="elbow_joint" pos="0 0 0" axis="0 1 0" limited="true" range="-3.14159 3.14159" />
                        <geom type="mesh" rgba="0.7 0.7 0.7 1" mesh="forearm" material="robot0:arm_mat"/>
                        <body name="wrist_1_link" pos="0 0 0.21325" quat="0.707107 0 0.707107 0">
                            <inertial pos="0 0 0" quat="0.5 0.5 -0.5 0.5" mass="0.8" diaginertia="0.00225 0.002085 0.002085" />
                            <joint name="wrist_1_joint" pos="0 0 0" axis="0 1 0" limited="true" range="-6.28319 6.28319" />
                            <geom type="mesh" rgba="0.7 0.7 0.7 1" mesh="wrist1" material="RobMat"/>
                            <body name="wrist_2_link" pos="0 0.08505 0">
                                <inertial pos="0 0 0" quat="0.5 0.5 -0.5 0.5" mass="0.8" diaginertia="0.00225 0.002085 0.002085" />
                                <joint name="wrist_2_joint" pos="0 0 0" axis="0 0 1" limited="true" range="-6.28319 6.28319" />
                                <geom type="mesh" rgba="0.7 0.7 0.7 1" mesh="wrist2" material="RobMat" />
                                <body name="wrist_3_link" pos="0 0 0.08535">
                                    <inertial pos="0 0 0" quat="0.5 0.5 -0.5 0.5" mass="0.35" diaginertia="0.000984375 0.000912187 0.000912187" />
                                    <joint name="wrist_3_joint" pos="0 0 0" axis="0 1 0" limited="true" range="-6.28319 6.28319" />
                                    <geom type="mesh" rgba="0.7 0.7 0.7 1" mesh="wrist3" material="RobMat"/>
                                    <body name="ee_link" pos="0 0.0819 0" euler = "-1.570796 0 0">
                                        <inertial pos="-0.01 0 0" mass="0.001" diaginertia="1.66667e-08 1.66667e-08 1.66667e-08" />
                                        <!--geom size="0.005 0.005 0.005" pos="-0.01 0 0" type="box" /-->
                                        <site name="EndEffector_visualize" type="box" pos="0 0 0.12" size="0.002 0.002 0.002"  quat = " 1.0 0.0  0.0 0."  />
                                        <site name="qcX" type="box" pos="0.05 0.0 0.12" size="0.05 0.002 0.002"  quat = " 1.0 0.0  0.0 0."     rgba="1 0 0 1" />
			                            <site name="qcY" type="box" pos="0.0 0.05 0.12" size="0.05 0.002 0.002"  quat = " 0.707107 0.0 0.0 0.707107"  rgba="0 1 0 1" />
			                            <site name="qcZ" type="box" pos="0.0 0.0 0.17" size="0.05 0.002 0.002"  quat = "-0.707107 0.0 0.707107 0."     rgba="0 0 1 1" />

                                        <!--camera name="gripper_camera" euler="0 3.14159265 0" fovy="63.5" /-->
                                        <geom name="light_1" type="sphere" size="0.005" pos="0.035 0 0.0166" material="Light" />
                                        <geom name="light_2" type="sphere" size="0.005" pos="-0.035 0 0.0166" material="Light" />
                                        <geom name="kinova_robotiq_coupler_mesh" type="mesh" mesh="kinova_robotiq_coupler" pos="0 0 0.0466" material="GriMat" />
                                        <geom name="robotiq_85_base_link_mesh" type="mesh" mesh="robotiq_85_base_link" pos="0 0 0.0016" quat="0.707107 0 -0.707107 0" material="GriMat" />

                                        <body name="right_driver" pos="0 -0.0306011 0.054904" quat="0.707107 0 -0.707107 0">
                                            <geom name="right_driver_mesh" rgba = "1 1 1 1" type="mesh" mesh="robotiq_85_knuckle_link" material="GriMat" contype="0" conaffinity="0" />
                                            <joint name="joint7_1" axis="0 0 1"  type="hinge" limited="true" range="0 0.872664626" />
                                            <site name="qcX7" type="box" pos="0.0 0.0 0.0" size="0.05 0.002 0.002"  quat = " 1.0 0.0  0.0 0."     rgba="1 0 0 1" />
	    		                            <site name="qcY7" type="box" pos="0.0 0.0 0.0" size="0.05 0.002 0.002"  quat = " 0.707107 0.0 0.0 0.707107"  rgba="0 1 0 1" />
    			                            <site name="qcZ7" type="box" pos="0.0 0.0 0.0" size="0.05 0.002 0.002"  quat = "-0.707107 0.0 0.707107 0."     rgba="0 0 1 1" />

                                                                                    
                                            <body name="right_coupler" pos="0 -0.0315 0">
                                                <geom name="right_coupler_mesh" rgba = "0 1 1 1" type="mesh" mesh="robotiq_85_finger_link" material="GriMat" contype="0" conaffinity="0" />
                                                <joint name="joint8_1" axis="0 0 1" type="hinge" limited="true" range="-1.57 2.967059728" />
                                                <site name="qcX8" type="box" pos="0.0 0.0 0.0" size="0.05 0.002 0.002"  quat = " 1.0 0.0  0.0 0."     rgba="1 0 0 1" />
	    		                                <site name="qcY8" type="box" pos="0.0 0.00 0.0" size="0.05 0.002 0.002"  quat = " 0.707107 0.0 0.0 0.707107"  rgba="0 1 0 1" />
    			                                <site name="qcZ8" type="box" pos="0.0 0.0 0.0" size="0.05 0.002 0.002"  quat = "-0.707107 0.0 0.707107 0."     rgba="0 0 1 1" />

                                            
                                                <body name="right_follower_link" pos="0.0475 -0.006 0">
                                                    <geom name="right_follower_mesh" rgba = "1 0 1 1" pos="0.0025 0.021 0" type="mesh" mesh="robotiq_85_finger_tip_link" material="GriMat" />
                                                    <joint name="joint9_1" axis="0 0 1" type="hinge" limited="true" range="-1.57  2.967059728" />
                                                    <site name="right_follower_1" type="box" rgba = "1 0 1 1" quat = "-0.707107 0.0 0.707107 0." pos="0.004 0.0175 0" size=".06 .001 .001"/>
                                                    

                                                    <site name="qcX9" type="box" pos="0.0 0.0 0.0" size="0.05 0.002 0.002"  quat = " 1.0 0.0  0.0 0."     rgba="1 0 0 1" />
	    		                                    <site name="qcY9" type="box" pos="0.0 0.00 0.0" size="0.05 0.002 0.002"  quat = " 0.707107 0.0 0.0 0.707107"  rgba="0 1 0 1" />
    			                                    <site name="qcZ9" type="box" pos="0.0 0.0 0.0" size="0.05 0.002 0.002"  quat = "-0.707107 0.0 0.707107 0."     rgba="0 0 1 1" />
                                                    
                                                </body>

                                            </body>

                                        </body>

                                        <body name="right_spring_link" pos="0.0016 -0.012 0.0614" quat="0.707107 0 -0.707107 0">
                                            <geom name="right_spring_mesh" rgba = "1 1 0 1" type="mesh" pos="0 -0.0005 0.0016" mesh="robotiq_85_inner_knuckle_link" material="GriMat" contype="0" conaffinity="0" />
                                            <joint name="joint10_1" axis="0 0 1" type="hinge" limited="true" range="0 1.57" />
                                            <site name="qcX10" type="box" pos="0.0 0.0 0.0" size="0.05 0.002 0.002"  quat = " 1.0 0.0  0.0 0."     rgba="1 0 0 1" />
	    		                            <site name="qcY10" type="box" pos="0.0 0.0 0.0" size="0.05 0.002 0.002"  quat = " 0.707107 0.0 0.0 0.707107"  rgba="0 1 0 1" />
    			                            <site name="qcZ10" type="box" pos="0.0 0.0 0.0" size="0.05 0.002 0.002"  quat = "-0.707107 0.0 0.707107 0."     rgba="0 0 1 1" />
                                            
                                            <site name="qcX10_1" type="box" pos="0.0447 -0.038 0.0" size="0.05 0.002 0.002"  quat = " 1.0 0.0  0.0 0."     rgba="1 0 0 1" />
	    		                            <site name="qcY10_1" type="box" pos="0.0447 -0.038 0.0" size="0.05 0.002 0.002"  quat = " 0.707107 0.0 0.0 0.707107"  rgba="0 1 0 1" />
    			                            <site name="qcZ10_1" type="box" pos="0.0447 -0.038 0.0" size="0.05 0.002 0.002"  quat = "-0.707107 0.0 0.707107 0."     rgba="0 0 1 1" />
                                        </body>


                                        <body name="left_driver" pos="0 0.0306011 0.054904" quat="0 0.707107 0 0.707107">
                                            <geom name="left_driver_mesh" type="mesh" mesh="robotiq_85_knuckle_link" material="GriMat" contype="0" conaffinity="0" />
                                            <joint name="joint7_2" axis="0 0 1" type="hinge" limited="true" range="0 0.872664626" />

                                        
                                            <body name="left_coupler" pos="0 -0.0315 0">
                                                <geom name="left_coupler_mesh" type="mesh" mesh="robotiq_85_finger_link" material="GriMat" contype="0" conaffinity="0" />
                                                <joint name="joint8_2" axis="0 0 1" type="hinge" limited="true" range="0 2.967059728" />

                                                <body name="left_follower_link" pos="0.0475 -0.006 0">
                                                    <geom name="left_follower_mesh" pos="0.0025 0.021 0" type="mesh" mesh="robotiq_85_finger_tip_link" material="GriMat" />
                                                    <joint name="joint9_2" axis="0 0 1" type="hinge" limited="true" range="0 2.967059728" />
                                                    <site name="left_follower_1" pos="0.02 0.03 0 " size=".006 .014 .014"/>
                                                </body>

                                            </body>

                                        </body>

                                        <body name="left_spring_link" pos="0.0016 0.012 0.0614" quat="0 0.707107 0 0.707107">
                                            <geom name="left_spring_mesh" type="mesh" pos="0 0.0005 0.0016" mesh="robotiq_85_inner_knuckle_link" material="GriMat" contype="0" conaffinity="0" />
                                            <joint name="joint10_2" axis="0 0 1" type="hinge" limited="true" range="0 1" />
                                        </body>

                                    </body>
                                     <!--body name="tool0" pos="0 0.0819 0" quat="0.707107 -0.707107 0 0">
                                        <inertial pos="0 0.0819 0" quat="0.707107 -0.707107 0 0" mass="0" diaginertia="0 0 0" />
                                    </body--> 
                                   
                                </body>
                            </body>
                        </body>
                    </body>
                </body>
            </body>
            <body name="base" pos="0 0 0" quat="1.7949e-09 0 0 -1">
                <inertial pos="0 0 0" quat="1.7949e-09 0 0 -1" mass="0" diaginertia="0 0 0" />
            </body>
        </body>
    </worldbody>
    
  
    
    <equality>
    <!-- GRIPPER Couplings -->
      
        <connect body1="right_follower_link" body2="right_spring_link" anchor="0.004 0.0175 0" solref = "0.02 0.15 "/>
        <joint name = "equal_r" joint1 ="joint7_1" joint2 = "joint8_1" polycoef="0 -1.1 0 0 0" solref = "0.02 1 "/>
        <joint name = "fix_r" joint1 ="joint8_1" joint2 = "joint9_1" polycoef = "0.15 0.2 0 0 0 " solref = "0.02 0.2 "/>
        
        <connect body1="left_follower_link" body2="left_spring_link" anchor="0.004 0.0175 0" solref = "0.02 0.15 "/>
        <joint name = "equal_l" joint1 ="joint7_2" joint2 = "joint8_2" polycoef="0 -1.1 0 0 0" solref = "0.02 1.3 "/>
        <joint name = "fix_l" joint1 ="joint8_2" joint2 = "joint9_2" polycoef = "0.15 0.2 0 0 0 " solref = "0.02 0.2 "/>
        
        <!--joint name = "equal_left_right" joint1 ="joint7_1" joint2 = "joint7_2" polycoef = "0 1 0 0 0 " solref = "0.02 0.1 "/-->
                
    </equality>

     <actuator>
    
        <!--velocity name="joint1_velocity" joint="joint1" ctrllimited="true" ctrlrange="-5 5" kv="5"/>
        <velocity name="joint2_velocity" joint="joint2" ctrllimited="true" ctrlrange="-5 5" kv="5"/>
        <velocity name="joint3_velocity" joint="joint3" ctrllimited="true" ctrlrange="-5 5" kv="5"/>
        <velocity name="joint4_velocity" joint="joint4" ctrllimited="true" ctrlrange="-3 3" kv="3"/>
        <velocity name="joint5_velocity" joint="joint5" ctrllimited="true" ctrlrange="-3 3" kv="3"/>
        <velocity name="joint6_velocity" joint="joint6" ctrllimited="true" ctrlrange="-3 3" kv="3"/-->

        <!--velocity name="joint1_velocity" joint="joint1" ctrllimited="true" ctrlrange="-10 10" kv="10"/>
        <velocity name="joint2_velocity" joint="joint2" ctrllimited="true" ctrlrange="-10 10" kv="10"/>
        <velocity name="joint3_velocity" joint="joint3" ctrllimited="true" ctrlrange="-10 10" kv="10"/>
        <velocity name="joint4_velocity" joint="joint4" ctrllimited="true" ctrlrange="-5 5" kv="5"/>
        <velocity name="joint5_velocity" joint="joint5" ctrllimited="true" ctrlrange="-5 5" kv="5"/>
        <velocity name="joint6_velocity" joint="joint6" ctrllimited="true" ctrlrange="-5 5" kv="5"/-->
        
        

        <position name="joint1_position" joint="shoulder_pan_joint" ctrllimited="true" ctrlrange="-3.14159 3.14159" kp="1"/>
        <position name="joint2_position" joint="shoulder_lift_joint" ctrllimited="true" ctrlrange="-3.14159 3.14159" kp="1"/>
        <position name="joint3_position" joint="elbow_joint" ctrllimited="true" ctrlrange="-3.14159 3.14159" kp="1"/>
        <position name="joint4_position" joint="wrist_1_joint" ctrllimited="true" ctrlrange="-3.14159 3.14159" kp="1"/>
        <position name="joint5_position" joint="wrist_2_joint" ctrllimited="true" ctrlrange="-3.14159 3.14159" kp="1"/>
        <position name="joint6_position" joint="wrist_3_joint" ctrllimited="true" ctrlrange="-3.14159 3.14159" kp="1"/>
        <position name="close_r" joint="joint7_1" ctrllimited="true" ctrlrange="-1 1" kp="1"/>
        <position name="close_l" joint="joint7_2" ctrllimited="true" ctrlrange="-1 1" kp="1"/>
        
        
        <!--gear="1.2" 였음-->
        <!--motor name="joint1_motor" joint="joint1" ctrllimited="true" ctrlrange="-2 2" gear="101"/> 
        <motor name="joint2_motor" joint="joint2" ctrllimited="true" ctrlrange="-2 2" gear="101"/>
        <motor name="joint3_motor" joint="joint3" ctrllimited="true" ctrlrange="-2 2" gear="101"/>
        <motor name="joint4_motor" joint="joint4" ctrllimited="true" ctrlrange="-1 1" gear="101"/>
        <motor name="joint5_motor" joint="joint5" ctrllimited="true" ctrlrange="-1 1" gear="101"/>
        <motor name="joint6_motor" joint="joint6" ctrllimited="true" ctrlrange="-1 1" gear="101"/-->
        <!--motor name="close_1" joint="joint7_1" gear="1 0 0 0 0 0" /> 
        <motor name="close_2" joint="joint7_2" gear="1 0 0 0 0 0" /-->

    </actuator>

</mujoco>
